#### 错误处理

> 错误码：函数返回值，易与正常返回值混淆，且一级一级向上报
>
> 错误处理机制：高级语言内置的`try...except...finally...`
>
> `Python`语言为`try...except...[else...][finally...]`

#####  跨越多层调用

```python

def foo(s):
    return 10 / int(s)

def bar(s):
    return foo(s) * 2

def main():
    while True:
        x = int(input('x:'))
        try:
            y = bar(x)
        except Exception as e:
            print('Error:', e)
        else:
            print(y)
        finally:
            print('finally...')

main()
```

##### 通过分析错误的调用栈信息定位错误的位置。

```python
def foo(s):
    return 10 / int(s)

def bar(s):
    return foo(s) * 2

def main():
    bar('0')

main()
```

上诉代码没有异常处理机制，出现异常会如下所示：

```python
Traceback (most recent call last):
  File "except2.py", line 10, in <module>
    main()
  File "except2.py", line 8, in main
    bar('0')
  File "except2.py", line 5, in bar
    return foo(s) * 2
  File "except2.py", line 2, in foo
    return 10 / int(s)
ZeroDivisionError: division by zero
```

##### 通过`logging`把错误记叙到日志文件中，便于事后排查

```python

import logging

def foo(s):
    return 10 / int(s)

def bar(s):
    return foo(s) * 2

def main():
    try:
        y = bar('0')
    except Exception as e:
        logging.exception(e)

main()
print('END')
```

输出：

```python
ERROR:root:division by zero
Traceback (most recent call last):
  File "except3.py", line 12, in main
    y = bar('0')
  File "except3.py", line 8, in bar
    return foo(s) * 2
  File "except3.py", line 5, in foo
    return 10 / int(s)
ZeroDivisionError: division by zero
END
```

##### 自定义错误

```python
class FooError(ValueError):
    pass

def foo(s):
    n = int(s)
    if n == 0:
        raise FooError('invalid value %s' %s)
    return 10 / n

foo('0')
```

输出：

```python
Traceback (most recent call last):
  File "except4.py", line 11, in <module>
    foo('0')
  File "except4.py", line 8, in foo
    raise FooError('invalid value %s' %s)
__main__.FooError: invalid value 0
```

尽量使用`Python`内置的错误类型。

##### `raise`向上抛出错误

```python
def foo(s):
    n = int(s)
    if n == 0:
        raise ValueError('invalid value %s' %s)
    return n / 10

def bar():
    try:
        foo('0')
    except ZeroDivisionError as e:
        print('ZeroDivisionError')
        raise	
        # raise ValueError

bar()
```

不带参数抛出原样错误，也可以抛出其他类型的错误，确保逻辑合理

#### 调试

- 通过`print()`打印有问题的变量,后期需要删除或注释

- 使用`assert`断言代替`print()`，可使用`python -O xxx.py`关闭`assert`

  ```python
  def foo(s):
      n = int(s)
      assert n != 0, 'n is zero'
      return 10 / n
  
  foo('0')
  ```

- 用`logging`代替`print()`

  ```python
  import logging
  logging.basicConfig(level=logging.INFO)
  
  def foo(s):
      n = int(s)
      logging.info('n = %d' % n)
      print(10 / n)
  
  foo('0')
  ```

  输出：

  ```python
  INFO:root:n = 0
  Traceback (most recent call last):
    File "debug2.py", line 9, in <module>
      foo('0')
    File "debug2.py", line 7, in foo
      print(10 / n)
  ZeroDivisionError: division by zero
  ```

  `logging`可指定记录信息的级别从低到高依次为：`debug`, `info`, `warning`, `error`，当指定`level=logging.INFO`时，`logging.debug`就不起作用，指定`level=logging.WARNING`，`debug`和`info`就不起作用，可输出不同层级的信息。`logging`可以通过简单的配置输送到控制台和文件。

- `pdb`调试器，让程序以单步运行和查看运行状态，输入`python -m pdb xxx.py`启动

  - `n`单步执行，`l`查看代码，`p`查看变量，`q`结束，`s`陷入函数， `c`继续执行，`b`设置断点，……

  - 在代码中设置断点：

    ```python
    import pdb
    import logging
    logging.basicConfig(level=logging.WARNING)
    
    def foo(s):
        n = int(s)
        pdb.set_trace() # 运行到这里会自动暂停
        logging.info('n = %d' % n)
        print(10 / n)
    
    x = foo('0')
    print(x)
    ```

  - `IDE`调试

#### 单元测试

需进行测试的模块：

```python
# mydict.py

class Dict(dict):

    def __init__(self, **kw):
        super().__init__(**kw)

    def __getattr__(self, key):
        try:
            return self[key]
        except KeyError:
            raise AttributeError(r"'Dict' object has no attribute '%s'" % key)

    def __setattr__(self, key, value):
        self[key] = value
```

单元测试模块，引入`Python`自带的`unittest`模块。

```python
# mydict_test.py

import unittest
from mydict import Dict

class TestDict(unittest.TestCase):

    def setUp(self):
        print('setUp...')

    def tearDown(self):
        print('tearDown...')

    def test_init(self):
        d = Dict(a=1, b='test')
        self.assertEqual(d.a, 1)
        self.assertEqual(d.b, 'test')
        self.assertTrue(isinstance(d, dict))

    def test_key(self):
        d = Dict()
        d['key'] = 'value'
        self.assertEqual(d.key, 'value')

    def test_attr(self):
        d = Dict()
        d.key = 'value'
        self.assertTrue('key' in d)
        self.assertEqual(d['key'], 'value')
        
    def test_keyerror(self):
        d = Dict()
        with self.assertRaises(KeyError):
            value = d['empty']

    def test_attrerror(self):
        d = Dict()
        with self.assertRaises(AttributeError):
            value = d.empty

if __name__ == '__main__':
    unittest.main()
```

使用`python mydict_test.py`和`python -m unittest mydict_test`（可加载多个模块）进行测试：

```python
# 测试结果

setUp...
tearDown...
.setUp...
tearDown...
.setUp...
tearDown...
.setUp...
tearDown...
.setUp...
tearDown...
.
----------------------------------------------------------------------
Ran 5 tests in 0.003s

OK
```

**要点：**

- 测试方法须以`test`开头
- `setUp`与`tearDown`方法会在每一个测试方法前后执行，可用于启动（关闭）如数据库等相关资源

```python
# student_unittest

class Student(object):
    def __init__(self, name, score):
        self.name = name
        self.score = score
    def get_grade(self):
        if self.score < 0 or self.score > 100:
            raise ValueError
        if self.score >= 80:
            return 'A'
        if self.score >= 60:
            return 'B'
        return 'C'
#--------------------------------------------

import unittest
class TestStudent(unittest.TestCase):

    def test_80_to_100(self):
        s1 = Student('Bart', 80)
        s2 = Student('Lisa', 100)
        self.assertEqual(s1.get_grade(), 'A')
        self.assertEqual(s2.get_grade(), 'A')

    def test_60_to_80(self):
        s1 = Student('Bart', 60)
        s2 = Student('Lisa', 79)
        self.assertEqual(s1.get_grade(), 'B')
        self.assertEqual(s2.get_grade(), 'B')

    def test_0_to_60(self):
        s1 = Student('Bart', 0)
        s2 = Student('Lisa', 59)
        self.assertEqual(s1.get_grade(), 'C')
        self.assertEqual(s2.get_grade(), 'C')

    def test_invalid(self):
        s1 = Student('Bart', -1)
        s2 = Student('Lisa', 101)
        with self.assertRaises(ValueError):
            s1.get_grade()
        with self.assertRaises(ValueError):
            s2.get_grade()

if __name__ == '__main__':
    unittest.main()
```

总结：

- 单元测试可有效测试某个程序模块的行为，是未来重构代码的信息保证
- 单元测试的测试用例要覆盖常用的输入组合、边界条件和异常
- 单元测试的代码要非常简单，复杂的测试代码本身可能会藏有`bug`
- 单元测试通过并不意味程序没有`bug`，但是未通过肯定有`bug`（前提是单元测试模块无`bug`）

#### 文档测试

`Python`内置的`doctest`模块可直接提取注释中的代码并执行测试

```python
# mydict_doctest.py

class Dict(dict):
    '''
    Simple dict but also support access as x.y style.

    >>> d1 = Dict()
    >>> d1['x'] = 100
    >>> d1.x
    100
    >>> d1.y = 200
    >>> d1['y']
    200
    >>> d2 = Dict(a=1, b=2, c='3')
    >>> d2.c
    '3'
    >>> d2['empty']
    Traceback (most recent call last):
        ...
    KeyError: 'empty'
    >>> d2.empty
    Traceback (most recent call last):
        ...
    AttributeError: 'Dict' object has no attribute 'empty'
    '''
    def __init__(self, **kw):
        super().__init__(**kw)

    def __getattr__(self, key):
        try:
            return self[key]
        except KeyError:
            raise AttributeError(r"'Dict' object has no attribute '%s'" % key)

    def __setattr__(self, key, value):
        self[key] = value

if __name__ == '__main__':
    import doctest
    doctest.testmod()
```

如果什么输出也没有则说明测试通过，注释`__getattr__`，则会输出：

```python
# 注释 `__getattr__` 输出
**********************************************************************
File "mydict.py", line 9, in __main__.Dict
Failed example:
    d1.x
Exception raised:
    Traceback (most recent call last):
      File "C:\Users\zLimbo\AppData\Local\Programs\Python\Python38\lib\doctest.py", line 1336, in __run
        exec(compile(example.source, filename, "single",
      File "<doctest __main__.Dict[2]>", line 1, in <module>
        d1.x
    AttributeError: 'Dict' object has no attribute 'x'
**********************************************************************
File "mydict.py", line 15, in __main__.Dict
Failed example:
    d2.c
Exception raised:
    Traceback (most recent call last):
      File "C:\Users\zLimbo\AppData\Local\Programs\Python\Python38\lib\doctest.py", line 1336, in __run
        exec(compile(example.source, filename, "single",
      File "<doctest __main__.Dict[6]>", line 1, in <module>
        d2.c
    AttributeError: 'Dict' object has no attribute 'c'
**********************************************************************
1 items had failures:
   2 of   9 in __main__.Dict
***Test Failed*** 2 failures.
```

当导入模块时`doctest`不会执行。

```python
def fact(n):
    '''
    Calculate 1*2*...*n
    
    >>> fact(1)
    1
    >>> fact(10)
    3628800
    >>> fact(-1)
    Traceback (most recent call last):
        ...
    ValueError
    '''
    if n < 1:
        raise ValueError()
    if n == 1:
        return 1
    return n * fact(n - 1)

if __name__ == '__main__':
    import doctest
    doctest.testmod()
```

文档生成工具可提取测试代码作为示例代码。